Workbook

Sheet Instructivo
B2: INSTRUCTIVO DEL INSTRUMENTO DE MONITOREO DEL FUNCIONAMIENTO DE LAS REDES INTEGRADAS DE SALUD INICIADORAS
B6: FINALIDAD Este instrumento tiene como finalidad monitorear el funcionamiento de las Redes Integradas de Salud Iniciadoras, considerando los aspectos generales y líneas de intervención de RIS Iniciadoras. ÁMBITO DE APLICACIÓN RIS Iniciadoras a nivel nacional PERIODICIDAD Trimestral RESPONSABLES DE LA APLICACIÓN MINSA, DIRESA/GERESA/DIRIS
B8: ESTRUCTURA DEL INSTRUMENTO El instrumento está estructurado en 12 componentes: a. Aspectos Generales para el funcionamiento de RIS iniciadoras. b. Línea de intervención 1: Nominalización y Georreferenciación de la población. c. Línea de Intervención 2: Conformación de EMS. d. Línea de Intervención 3: Organización de las rutinas de trabajo de los EMS. e. Línea de Intervención 4: Prestaciones de salud para la atención de salud especializada en los E.S. del I NAS de la RIS. f. Línea de intervención 5: Centralización de la UPSS Patología Clínica en la RIS. g. Línea de Intervención 6: Historia Clínica electrónica y otras herramientas digitales en la RIS. h. Línea de intervención 7: Vía de Cuidado Integral en Salud - VCIS i. Línea de intervención 8: Gestión de un programa de enfermedades crónicas en la RIS desde los servicios de salud. j. Línea de intervención 9: Metas clínicas para la gestión de los usuarios con enfermedades crónicas en los servicios de salud k. Línea de intervención 10: Financiamiento en la RIS l. Línea de intervención 11: Gobernanza y Gestión de los Determinantes sociales de la salud, Estos componentes agrupan cuarenta y siete (47) verificadores, por cada verificador existe una fuente auditable que permite medir el funcionamiento de la RIS Iniciadora. Asimismo, al lado derecho de cada verificador existe una casilla llamada observaciones que permite describir hallazgos relevantes, precisiones sobre la evidencia revisada, brechas identificadas, entre otros.
B10: CALIFICACIÓN Cada verificador es calificado en la siguiente escala: a. Cumple: 2 b. En proceso: 1 c. No Cumple: 0 La valoración se escribe en las celdas de calificar, cada celda contiene un valor numérico (0, 1 o 2) desplegable, asignado de acuerdo al cumplimiento de las fuentes auditables de los verificadores. El equipo monitor es responsable de verificar la existencia de las fuentes auditables, para ello la RIS deberá mostrar los documentos, reportes u otros según corresponda. Cuando un verificador es calificado con el valor cero (0) se muestra de color rojo, con el valor uno (1) de amarillo y con el valor dos (2) de color verde. Si no marca nada se considera cero (0) y de color rojo. Al calificar todos verificadores del instrumento se obtiene el valor por cada componente y de manera general. Todos los cálculos son automáticos, solo debe calificarse cada verificador.
B12: PRECISIONES ADICIONALES El equipo monitor es responsable de la aplicación de la herramienta en la RIS Iniciadora y de la revisión del cumplimiento según fuentes auditables. En la aplicación de la herramienta debe participar representantes de la DIRES/GERESA/DIRIS, cuando la aplicación es por parte del MINSA. Los resultados obtenidos son socializados con el equipo de la RIS Iniciadora y se firma un acta de acuerdos.
B14: RESULTADOS La puntuación obtenida por componentes y de manera global, se muestra en la pestaña Resultados.

Sheet Herramienta de Monitoreo
A1: INSTRUMENTO DE MONITOREO DEL FUNCIONAMIENTO DE LAS RIS INICIADORAS
A3: DIRESA/GERESA/DIRIS: | B3: xxx
A4: RIS: | B4: xxx
A5: Fecha: | B5: xxx
A6: Equipo Monitor: | B6: xxx
B7: xxx
B8: xxx
A10: Aspectos/Lineas de Intervención | B10: N° | C10: Verificadores | D10: Fuentes auditables | E10: Especificaciones para asignación de puntaje | F10: Calificación (0: no cumple 1: cumple parcial 2: cumple) | G10: Unidad de Medida | H10: Observaciones
A11: Aspectos Generales para el funcionamiento de RIS iniciadoras | B11: 1 | C11: Los Gestores de la RIS están formalizados, según el D.S. 019-2024. | D11: Acto administrativo (Resolución, Memorando) de conformación vigente emitido por la ARS o DIRIS LM. | E11: Cumple (2): Evidencia del acto administrativo (Resolución, Memorando) de conformación vigente emitido por la ARS o DIRIS LM. En proceso (1): Evidencia de las gestiones realizadas para la formalización de los Gestores de la RIS (propuesta de acto administrativo, inicio de trámite, entre otros). No cumple (0): No se evidencia acciones realizadas. | F11: 0 | G11: 1 Resolución
B12: 2 | C12: Los Gestores de la RIS cuentan con funciones asignadas y las ejecutan. | D12: 1. Documento de asignación de funciones (Memorando u otro) a los Gestores de la RIS. 2. Documento que evidencie el ejercicio de las funciones (informes, Actas). | E12: Cumple (2): Evidencia del cumplimiento de las dos fuentes auditables. En proceso (1): Evidencia del cumlimiento de una de las fuentes auditables. No cumple (0): No se evidencia acciones realizadas. | F12: 1 | G12: 1 documento de asignación de funciones 1 documento del ejercicio de las funciones
B13: 3 | C13: La RIS cuenta con las condiciones de salud trazadoras, seleccionadas. | D13: Acta de reunión que consigna la selección de condiciones de salud trazadoras. | E13: Cumple (2): Evidencia del acta firmada de selección de condiciones de salud trazadoras. En proceso (1): Evidencia de inicio de acciones o programación de reunión para selección de condiciones de salud trazadoras. No cumple (0): No se evidencia acciones realizadas. | F13: 0 | G13: 1 Acta
B14: 4 | C14: La RIS cuenta con resultados de la segunda medición del grado de integración de RIS según la metodología establecida(*). | D14: Acta de taller de la segunda medición del grado de integración de RIS o Acta de Taller de Medición de Línea de Base de la RIS, con una vigencia no mayor a dos (2) años. | E14: Cumple (2): Evidencia del acta de taller de segunda medición del grado de integración de RIS o Acta de Taller de Medición de Línea de Base de la RIS, con una vigencia no mayor a dos (2) años. En proceso (1): Evidencia de inicio de acciones o programación de taller de segunda medición (coordinaciones iniciales, inicio del registro del instrumento, entre otros.) No cumple (0): No se evidencia acciones realizadas. | F14: 0 | G14: 1 Acta
A15: Línea de intervención 1: Nominalización y Georreferenciación de la población | B15: 5 | C15: La RIS cuenta con el listado nominalizado único de la población con condición de salud trazadora para toda la RIS. | D15: 1.Listado nominalizado anonimizado correspondiente al año inmediato anterior (enero–diciembre) 2.Documento de socialización del listado nominalizado a los E.S. | E15: Cumple (2): Evidencia del cumplimiento de las dos fuentes auditables. En proceso (1): Evidencia del cumplimiento de una de las fuentes auditables. No cumple (0): No se evidencia acciones realizadas. | F15: 0 | G15: 1 Listado nominalizado 1 Documento de socialización
B16: 6 | C16: La RIS realiza el monitoreo trimestral de las acciones de actualización y seguimiento de pacientes con condiciones de salud trazadoras, según listado nominalizado, correspondiente al último trimestre concluido. | D16: Informe del monitoreo trimestral correspondiente al último trimestre concluido, que contenga el listado nominalizado actualizado. | E16: Cumple (2): Evidencia del informe de monitoreo trimestral presentado a la ARS o DIRIS LM. En proceso (1): Evidencia de acciones de programación del monitoreo, proceso de elaboración de informe, entre otros. No cumple (0): No se evidencia acciones realizadas. | F16: 2 | G16: 1 informe trimestral
B17: 7 | C17: La RIS tiene georreferenciada la población con condiciones de salud trazadora del listado nominalizado. | D17: Reporte en GeoRIS, Herramienta y/o aplicativo de georreferenciación. | E17: Cumple (2): Evidencia de georreferenciación en aplicativo GeoRIS u otro de las condiciones de salud trazadoras actualizado al listado nominalizado. En proceso (1): Evidencia de acciones realizadas para el proceso de georreferenciación (gestiones realizadas, mapeo de herramientas, entre otras). No cumple (0): No se evidencia acciones realizadas. | F17: 0 | G17: 1 Reporte
A18: Línea de Intervención 2: Conformación de EMS | B18: 8 | C18: La RIS identifica los RHUS disponibles para la conformación de los EMS. | D18: Herramienta para el registro de los EMS de la RIS - Identificación del RHUS de la RIS. | E18: Cumple (2): Evidencia del registro completo de la herramienta para el registro de los EMS de la RIS: Identificación del RHUS de la RIS (parte 1). En proceso (1): Evidencia de acciones para la identificación de los RHUS disponibles (proceso de recojo de información, coordinaciones para identificar los RHUS disponibles, entre otros). No cumple (0): No se evidencia acciones realizadas. | F18: 0 | G18: 1 Registro completo en Herramienta
B19: 9 | C19: La RIS identifica las características del ámbito territorial (tamaño poblacional, densidad poblacional, entre otros) y oferta de servicios de salud disponibles para definir el número y la conformación de EMS. | D19: Herramienta para el registro de los EMS de la RIS - Organización del RHUS en EMS por cada E.S. | E19: Cumple (2): Evidencia del registro completo de la herramienta para el registro de los EMS de la RIS: Organización del RHUS en EMS por cada E.S. (parte 2). En proceso (1): Evidencia de las gestiones realizadas para la conformación de los EMS (reuniones, talleres u otros relacionados). No cumple (0): No se evidencia acciones realizadas. | F19: 0 | G19: 1 Registro completo en Herramienta
B20: 10 | C20: La RIS cuenta con EMS conformados y formalizados. | D20: 1. Acto administrativo vigente (Resolución, Memorando) que formaliza el EMS por sector sanitario. 2. Herramienta para el registro de los EMS de la RIS - Determinación del número de EMS por E.S. de la RIS e identificación de la brecha indirecta. | E20: Cumple (2): Evidencia del cumplimiento de las dos fuentes auditables. En proceso (1): Evidencia del cumplimiento de una de las fuentes auditables. No cumple (0): No se evidencia acciones realizadas. | F20: 0 | G20: 1 Resolución 1 Registro completo en Herramienta
B21: 11 | C21: Los Gestores de la RIS realizan las gestiones para el cierre de brechas de EMS. | D21: Documentos (oficios, planes, entre otros) de los pedidos de RHUS a la ARS o DIRIS LM. | E21: Cumple (2): Evidencia de documentos formales de la gestión para el cierre de brechas de EMS. En proceso (1): Evidencia de acciones realizadas (actas, reuniones u otros) para el cierre de brechas de EMS. No cumple (0): No se evidencia acciones realizadas. | F21: 2 | G21: Documentos de gestiones realizadas
B22: 12 | C22: Los Gestores de la RIS actualizan la conformación de los EMS de manera semestral. | D22: Herramienta para el registro de los EMS de la RIS - Organización del RHUS en EMS por cada E.S. actualizado al último semestre concluido. | E22: Cumple (2): Evidencia del registro actualizado de la parte 2: Organización del RHUS en EMS por cada E.S. En proceso (1): Evidencia de acciones para el registro de la parte 2: Organización del RHUS en EMS por cada E.S. (registros iniciales, coordinaciones para la actualización). No cumple (0): No se evidencia acciones realizadas. | F22: 2 | G22: 1 Registro en Herramienta actualizado.
A23: Línea de Intervención 3: Organización de las rutinas de trabajo de los EMS | B23: 13 | C23: Los Gestores de la RIS realizan o gestionan las capacitaciones en rutinas de trabajo a los EMS. | D23: 1.Documentos de convocatoria a la capacitación 2.Plan de capacitación 3.Informe de la capacitación realizada. | E23: Cumple (2): Evidencia del cumplimiento de las tres fuentes auditables. En proceso (1): Evidencia del cumplimiento de al menos una de las fuentes auditables. No cumple (0): No se evidencia acciones realizadas. | F23: 2 | G23: 1 informe
B24: 14 | C24: Los Gestores de la RIS monitorean el cumplimiento de la asignación de tareas del EMS por condición de salud trazadora por E.S. | D24: Acta o informe del monitoreo trimestral realizado. | E24: Cumple (2): Evidencia de la elaboración del informe de monitoreo realizado. En proceso (1): Evidencia de las gestiones realizadas para el monitoreo (programación del monitoreo, coordinaciones previas, entre otros). No cumple (0): No se evidencia acciones realizadas. | F24: 2 | G24: 1 informe trimestral
B25: 15 | C25: Los Gestores de la RIS en coordinación con los EMS de los E.S. elaboran los flujos de atención referencial de la condición de salud trazadora para su ámbito. | D25: 1.Informe de flujos elaborados. 2. Documento de la socialización del flujo referencial a los E.S. | E25: Cumple (2): Evidencia del cumplimiento de las dos fuentes auditables. El informe debe ser remitido a la ARS o DIRIS LM. En proceso (1): Evidencia del cumplimiento de al menos una de las fuentes auditables. No cumple (0): No se evidencia acciones realizadas. | F25: 1 | G25: 1 Informe
B26: 16 | C26: Los Gestores de la RIS realizan el monitoreo trimestral de la operación de los flujos de atención adecuados en los E.S. correspondiente al último trimestre concluido. | D26: 1.Cronograma de monitoreo trimestral. 2.Informe de monitoreo trimestral correspondiente al último trimestre concluido. | E26: Cumple (2): Evidencia del cumplimiento de las dos fuentes auditables. El informe debe ser remitido a la ARS o DIRIS LM. En proceso (1): Evidencia del cumplimiento de una de las fuentes auditables. No cumple (0): No se evidencia acciones realizadas. | F26: 1 | G26: 1 informe trimestral
B27: 17 | C27: Los Gestores de la RIS realizan acciones de mejora para el cumplimiento de las rutinas de trabajo del EMS. | D27: Documento (informe) de acciones de mejora realizadas. | E27: Cumple (2): Evidencia del informe de las acciones de mejora realizadas remitida a la ARS o DIRIS LM. En proceso (1): Evidencia de acciones realizadas (propuesta de acto administrativo, inicio de trámite, entre otros). No cumple (0): No se evidencia acciones realizadas. | F27: 1 | G27: Documentos de gestiones realizadas
A28: Línea de Intervención 4: Prestaciones de salud para la atención de salud especializada en los E.S. del I NAS de la RIS | B28: 18 | C28: Los Gestores de la RIS identifican a los profesionales de la salud especialistas disponibles en su ámbito y los recursos tecnológicos. | D28: 1. Listados nominalizados de profesionales médicos y profesionales de la salud especialistas por E.S. 2. Listado de recursos tecnológicos en salud. | E28: Cumple (2): Evidencia del cumplimiento de las dos fuentes auditables. En proceso (1): Evidencia del cumplimiento de una de las fuentes auditables. No cumple (0): No se evidencia acciones realizadas. | F28: 1 | G28: 1 Listado nominalizado de profesionales de la salud 1 Listado de Recursos Tecnológicos en Salud
B29: 19 | C29: Los Gestores de la RIS, previo análisis, seleccionan los E.S. para brindar prestaciones de salud para la atención de salud especializada en su ámbito. | D29: 1.Listado de E.S. seleccionados 2.Informe de análisis realizado sobre E.S. seleccionados. | E29: Cumple (2): Evidencia del cumplimiento de las dos fuentes auditables. El informe debe ser remitido a la ARS o DIRIS LM. En proceso (1): Evidencia del cumplimiento de una de las fuentes auditables. No cumple (0): No se evidencia acciones realizadas. | F29: 2 | G29: 1 informe
B30: 20 | C30: Los Gestores de la RIS gestionan el cierre de brechas para brindar prestaciones de salud para la atención de salud especializadas. | D30: Informe de acciones de gestión de cierre de brechas (incluye RHUS, Recursos tecnológicos, entre otros). | E30: Cumple (2): Evidencia del cumplimiento del informe de acciones de gestión de cierre de brechas presentado formalmente a la ARS o DIRIS LM según corresponda. En proceso (1): Evidencia de las gestiones realizadas para el cierre de brechas (requerimiento de profesionales o recursos tecnológicos, actas de reuniones de coordinaciones, entre otras). No cumple (0): No se evidencia acciones realizadas. | F30: 2 | G30: 1 informe
B31: 21 | C31: Los Gestores de la RIS monitorean que los E.S. brinden prestaciones de salud para la atención de salud especializadas mediante oferta fija, móvil y telesalud de manera complementaria. | D31: 1.cronograma de monitoreo trimestral. 2.Reportes de atención especializada (oferta fija, móvil y telesalud), incluye tablero de indicadores, reportes HIS, FUA, entre otros. 3. Informe de monitoreo trimestral | E31: Cumple (2): Evidencia del cumplimiento de las dos fuentes auditables. Los reportes deben evidenciar atenciones especializadas desde la puesta en marcha de dichas prestaciones. En proceso (1): Evidencia del cumplimiento de una de las fuentes auditables. No cumple (0): No se evidencia acciones realizadas. | F31: 2 | G31: 1 informe trimestral
A32: Línea de intervención 5: Centralización de la UPSS Patología Clínica en la RIS | B32: 22 | C32: Los Gestores de la RIS seleccionan los E.S en los cuales se ubicará la UPSS Patología Clínica centralizada y las UTM. | D32: Informe de E.S. seleccionados según herramienta de recojo de información. | E32: Cumple (2): Evidencia del envío del informe a la ARS o DIRIS LM, que contiene la herramienta de recojo de información completa. En proceso (1): Evidencia de acciones realizadas para seleccionar los E.S. (actas de reuniones, coordinaciones para el recojo de información, avances del registro de la herramienta, entre otros.) No cumple (0): No se evidencia acciones realizadas. | F32: 2 | G32: 1 informe
B33: 23 | C33: Los Gestores de la RIS gestionan la implementación de UPSS Patología Clínica centralizada. | D33: Documento (informe) que evidencie la implementación y puesta en marcha de la UPSS Patología Clínica centralizada. | E33: Cumple (2): Evidencia del cumplimiento y envío formal de de las fuente auditable a la ARS o DIRIS LM. En proceso (1): Evidencia de acciones para la implementación (análisis para el funcionamiento del laboratorio centralizado, gestiones para el equipamiento y dotación de personal para el laboratorio centralizado, entre otros). No cumple (0): No se evidencia acciones realizadas. | F33: 2 | G33: 1 informe
B34: 24 | C34: Los Gestores de la RIS gestionan la implementación de UTM. | D34: Documento (informe) que evidencie la implementación y puesta en marcha de las UTM | E34: Cumple (2): Evidencia del cumplimiento y envío formal de de las fuente auditable a la ARS o DIRIS LM. En proceso (1): Evidencia de acciones para la implementación (análisis para el funcionamiento del laboratorio centralizado, gestiones para el equipamiento y dotación de personal para el laboratorio centralizado, entre otros). No cumple (0): No se evidencia acciones realizadas. | F34: 2 | G34: 1 informe
B35: 25 | C35: La RIS cuenta con servicio de traslado de muestras para todo el ámbito de la RIS. | D35: Documento o contrato del servicio de traslado de muestras vigente. | E35: Cumple (2): Evidencia del cumplimiento de la fuente auditable. En proceso (1): Evidencia de las gestiones realizadas para el contrato del servicio de traslado de muestras en el ámbito de la RIS. No cumple (0): No se evidencia acciones realizadas. | F35: 2 | G35: 1 contrato de servicio de traslado de muestras
B36: 26 | C36: Los Gestores de la RIS realizan el monitoreo trimestral del funcionamiento de la UPSS Patología Clínica centralizada y de las UTM en los E.S. definidos. | D36: 1.Cronograma de monitoreo trimestral 2. Informe del monitoreo trimestral | E36: Cumple (2): Evidencia del cumplimiento de las dos fuentes auditables. En proceso (1): Evidencia del cumplimiento de una de las fuentes auditables. No cumple (0): No se evidencia acciones realizadas. | F36: 1 | G36: 1 informe trimestral
A37: Línea de Intervención 6: Historia Clínica electrónica y otras herramientas digitales en la RIS | B37: 27 | C37: Los Gestores de la RIS identifican la brecha de conectividad en los E.S. | D37: Informe de levantamiento de información sobre conectividad en el 100% de los E.S. de la RIS. | E37: Cumple (2): Evidencia del envío formal a la ARS o DIRIS LM del cumplimiento de la fuente auditable. En proceso (1): Evidencia de las gestiones realizadas para el levantamiento de información sobre conectividad (reuniones de coordinación, acciones en proceso, entre otros). No cumple (0): No se evidencia acciones realizadas. | F37: 2 | G37: 1 informe
B38: 28 | C38: Los Gestores de la RIS identifican la brecha de equipamiento tecnológico para el funcionamiento de la HCE. | D38: Informe de levantamiento de información sobre la brecha de estructura tecnológica y equipamiento (Equipos de cómputo, lectoras de DNIs, entre otros.), del 100% de los E.S. | E38: Cumple (2): Evidencia del envío formal a la ARS o DIRIS LM del cumplimiento de la fuente auditable. En proceso (1): Evidencia de las gestiones realizadas para el levantamiento de información (coordinaciones, acciones en proceso, entre otros). No cumple (0): No se evidencia acciones realizadas. | F38: 1 | G38: 1 informe
B39: 29 | C39: Los Gestores de la RIS monitorean trimestralmente el funcionamiento de la HCE en los E.S. definidos. | D39: 1.cronograma de monitoreo trimestral 2.Acta o informe de monitoreo. 3.Listado de E.S. con HCE en funcionamiento | E39: Cumple (2): Evidencia del cumplimiento de las tres fuentes auditables. En proceso (1): Evidencia del cumplimiento de al menos una de las fuentes auditables. No cumple (0): No se evidencia acciones realizadas. | F39: 1 | G39: 1 informe trimestral
B40: 30 | C40: Los Gestores de la RIS identifican y monitorean el uso de otras herramientas digitales para la atención en salud. | D40: 1.cronograma de monitoreo trimestral 2.Informe de uso de herramientas digitales en los E.S. | E40: Cumple (2): Evidencia del cumplimiento de las dos fuentes auditables. El informe debe ser remitido a la ARS o DIRIS LM. En proceso (1): Evidencia del cumplimiento de una de los dos fuentes auditables. No cumple (0): No se evidencia acciones realizadas. | F40: 1 | G40: 1 informe trimestral
A41: Línea de intervención 7: Vía de Cuidado Integral en Salud - VCIS | B41: 31 | C41: Los Gestores de la RIS identifican y priorizan la VCIS a implementar en su ámbito, considerando el listado de VCIS elaboradas por el MINSA. | D41: Documento (informe) de identificación y priorización de la VCIS. | E41: Cumple (2): Evidencia del envío del informe a la ARS o DIRIS LM. En proceso (1): Evidencia de las gestiones realizadas para la identificación y priorización de la VCIS. No cumple (0): No se evidencia acciones realizadas. | F41: 2 | G41: 1 informe
B42: 32 | C42: Los Gestores de la RIS realizan el proceso de adecuación de la VCIS identificada y esta ha sido aprobada por la ARS o DIRIS LM. | D42: Acto Resolutivo (Resolución) de la ARS o DIRIS LM que aprueba la VCIS que pasó adecuación. | E42: Cumple (2): Evidencia del cumplimiento de la fuente auditable. En proceso (1): Evidencia de acciones realizadas para la adecuación de la VCIS identificada (actas de reuniones, análisis realizados, adecuación en proceso, entre otros). No cumple (0): No se evidencia acciones realizadas. | F42: 0 | G42: 1 resolución
...

Sheet Resultados
B1: CONSOLIDADO POR COMPONENTES
B3: Aspectos/Lineas de Intervención | C3: Puntaje Obtenido | D3: Puntaje máximo | E3: % de cumplimiento | F3: Nivel de avance
B4: Aspectos Generales para el funcionamiento de RIS iniciadoras | C4: =SUM('Herramienta de Monitoreo'!F11:F14) -> 1 | D4: 8 | E4: =C4/D4*1 -> 0.125 | F4: =IF(E4="", "Sin datos", IF(E4<=0.3, "BAJO", IF(E4<=0.75, "EN PROCESO", "ÓPTIMO"))) -> BAJO
B5: Línea de intervención 1: Nominalización y Georreferenciación de la población | C5: =SUM('Herramienta de Monitoreo'!F15:F17) -> 2 | D5: 6 | E5: =C5/D5*1 -> 0.33333333 | F5: =IF(E5="", "Sin datos", IF(E5<=0.3, "BAJO", IF(E5<=0.75, "EN PROCESO", "ÓPTIMO"))) -> EN PROCESO
B6: Línea de Intervención 2: Conformación de EMS | C6: =SUM('Herramienta de Monitoreo'!F18:F22) -> 4 | D6: 10 | E6: =C6/D6*1 -> 0.4 | F6: =IF(E6="", "Sin datos", IF(E6<=0.3, "BAJO", IF(E6<=0.75, "EN PROCESO", "ÓPTIMO"))) -> EN PROCESO
B7: Línea de Intervención 3: Organización de las rutinas de trabajo de los EMS | C7: =SUM('Herramienta de Monitoreo'!F23:F27) -> 7 | D7: 10 | E7: =C7/D7*1 -> 0.7 | F7: =IF(E7="", "Sin datos", IF(E7<=0.3, "BAJO", IF(E7<=0.75, "EN PROCESO", "ÓPTIMO"))) -> EN PROCESO
B8: Línea de Intervención 4: Prestaciones de salud para la atención de salud especializada en los E.S. del I NAS de la RIS | C8: =SUM('Herramienta de Monitoreo'!F28:F31) -> 7 | D8: 8 | E8: =C8/D8*1 -> 0.875 | F8: =IF(E8="", "Sin datos", IF(E8<=0.3, "BAJO", IF(E8<=0.75, "EN PROCESO", "ÓPTIMO"))) -> ÓPTIMO
B9: Línea de intervención 5: Centralización de la UPSS Patología Clínica en la RIS | C9: =SUM('Herramienta de Monitoreo'!F32:F36) -> 9 | D9: 10 | E9: =C9/D9*1 -> 0.9 | F9: =IF(E9="", "Sin datos", IF(E9<=0.3, "BAJO", IF(E9<=0.75, "EN PROCESO", "ÓPTIMO"))) -> ÓPTIMO
B10: Línea de Intervención 6: Historia Clínica electrónica y otras herramientas digitales en la RIS | C10: =SUM('Herramienta de Monitoreo'!F37:F40) -> 5 | D10: 8 | E10: =C10/D10*1 -> 0.625 | F10: =IF(E10="", "Sin datos", IF(E10<=0.3, "BAJO", IF(E10<=0.75, "EN PROCESO", "ÓPTIMO"))) -> EN PROCESO
B11: Línea de intervención 7: Vía de Cuidado Integral en Salud - VCIS | C11: =SUM('Herramienta de Monitoreo'!F41:F44) -> 2 | D11: 8 | E11: =C11/D11*1 -> 0.25 | F11: =IF(E11="", "Sin datos", IF(E11<=0.3, "BAJO", IF(E11<=0.75, "EN PROCESO", "ÓPTIMO"))) -> BAJO
B12: Línea de intervención 8: Gestión de un programa de enfermedades crónicas en la RIS desde los servicios de salud | C12: =SUM('Herramienta de Monitoreo'!F45:F48) -> 7 | D12: 8 | E12: =C12/D12*1 -> 0.875 | F12: =IF(E12="", "Sin datos", IF(E12<=0.3, "BAJO", IF(E12<=0.75, "EN PROCESO", "ÓPTIMO"))) -> ÓPTIMO
B13: Línea de intervención 9: Metas clínicas para la gestión de los usuarios con enfermedades crónicas en los servicios de salud | C13: =SUM('Herramienta de Monitoreo'!F49:F50) -> 4 | D13: 4 | E13: =C13/D13*1 -> 1 | F13: =IF(E13="", "Sin datos", IF(E13<=0.3, "BAJO", IF(E13<=0.75, "EN PROCESO", "ÓPTIMO"))) -> ÓPTIMO
B14: Línea de intervención 10: Financiamiento en la RIS | C14: =SUM('Herramienta de Monitoreo'!F51:F52) -> 4 | D14: 4 | E14: =C14/D14*1 -> 1 | F14: =IF(E14="", "Sin datos", IF(E14<=0.3, "BAJO", IF(E14<=0.75, "EN PROCESO", "ÓPTIMO"))) -> ÓPTIMO
B15: Línea de intervención 11: Gobernanza y Gestión de los Determinantes sociales de la salud | C15: =SUM('Herramienta de Monitoreo'!F53:F57) -> 7 | D15: 10 | E15: =C15/D15*1 -> 0.7 | F15: =IF(E15="", "Sin datos", IF(E15<=0.3, "BAJO", IF(E15<=0.75, "EN PROCESO", "ÓPTIMO"))) -> EN PROCESO
B83: COMPONENTES | D83: % DE AVANCE
B84: 1 | C84: Aspectos Generales para el funcionamiento de RIS iniciadoras. | D84: %
B85: 2 | C85: Línea de intervención 1: Nominalización y Georreferenciación de la población. | D85: %
B86: 3 | C86: Línea de Intervención 2: Conformación de EMS. | D86: %
B87: 4 | C87: Línea de Intervención 3: Organización de las rutinas de trabajo de los EMS. | D87: %
B88: 5 | C88: Línea de Intervención 4: Prestaciones de salud para la atención de salud especializada en los E.S. del I NAS de la RIS. | D88: %
B89: 6 | C89: Línea de intervención 5: Centralización de la UPSS Patología Clínica en la RIS. | D89: %
B90: 7 | C90: Línea de Intervención 6: Historia Clínica electrónica y otras herramientas digitales en la RIS. | D90: %
B91: 8 | C91: Línea de intervención 7: Vía de Cuidado Integral en Salud - VCIS | D91: %
B92: 9 | C92: Línea de intervención 8: Gestión de un programa de enfermedades crónicas en la RIS desde los servicios de salud. | D92: %
B93: 10 | C93: Línea de intervención 9: Metas clínicas para la gestión de los usuarios con enfermedades crónicas en los servicios de salud | D93: %
B94: 11 | C94: Línea de intervención 10: Financiamiento en la RIS | D94: %
B95: 12 | C95: Línea de intervención 11: Gobernanza y Gestión de los Determinantes sociales de la salud, | D95: %
